异常
=======
##继承关系
Throwable
- **Exception**
  - ClassNotFoundException
  - IOException
  - **RuntimeException**
  - ...
- **Error**
  - LinkageError
  - VirtualMachineError
  - ...
  
##分类
异常类可以分为三种类型：
- 系统错误（Error）
- 异常（Exception）
- 运行时异常（RuntimeException）

##异常操作
|操作|描述
|----|----
|声明异常|在方法头中使用throws，如果父类方法没有声明异常，子类该方法就不能声明异常
|抛出异常|方法体内部使用throw
|捕获异常|try...catch块。运行时异常（RuntimeException）不需要被捕获

##自定义异常
继承Exception类，这时自定义的异常抛出后也要捕获。  
理论上可以继承RuntimeException，使得自定义的异常免检。但这不不是一个好方法。
##try块与返回值
本部分讨论内容来源于[CSDN博客](http://blog.csdn.net/exsuns/article/details/5217669)
###代码1
```java
class TestTryFinallyC {
	 public static void main(String[] args)  {
	        System.out.println(testt());
	    }
	    
	    public static int testt() {
	        int x = 99;
	    	try {
	        	return x;
	        }finally {
	            x = 8;
	        }
	    }
}
```
执行结果是:99
###代码2
对testt方法进行变形
```java
class TestTryFinallyC {
	 public static void main(String[] args)  {
	        System.out.println(testt());
	    }
	    
	    public static int testt() {
	        int x = 99;
	    	try {
	        	return x;
	    	}catch(Exception e){
	    		return x;
	        }finally {
	            x = 8;
	        }
	    }
}
```
执行结果依然是:99
>代码2.5
```java
//try中的return改为return x/0.使抛出异常
	    public static int testt() {
	        int x = 99;
	    	try {
	        	return x/0;
	    	}catch(Exception e){
	    		return x;
	        }finally {
	            x = 8;
	        }
	    }
 ```
 执行结果还是99


 ###代码3
 ```java
 class TestTryFinallyC {
	 public static void main(String[] args)  {
	        System.out.println(testt());
	    }
	    
	    public static int testt() {
	        int x = 99;
	    	try {
	        	return x;
	    	}catch(Exception e){   	
            
	        }finally {
	            x = 8;
	        }
	    	return x;//这里不加上这句会报错，缺少返回值
	    }
}
```
执行结果为:99
>代码3.5
```java
//try中的return改为return x/0.使抛出异常
 public static int testt() {
	        int x = 99;
	    	try {
	        	return x/0;
	    	}catch(Exception e){		
	        }finally {
	            x = 8;
	        }
	    	return x;//这里不加上这句会报错，缺少返回值
	    }
```
执行结果为:8
